<?xml version="1.0" ?>
<!-- =================================================================================== -->
<!-- |    This document was autogenerated by xacro from mir_600.gazebo.urdf            | -->
<!-- |    EDITING THIS FILE BY HAND IS NOT RECOMMENDED                                 | -->
<!-- =================================================================================== -->
<robot name="mir600">
  <material name="aluminum">
    <color rgba="0.5 0.5 0.5 1"/>
  </material>
  <material name="plastic">
    <color rgba="0.1 0.1 0.1 1"/>
  </material>
  <link name="base_footprint"/>
  <joint name="base_joint" type="fixed">
    <parent link="base_footprint"/>
    <child link="base_link"/>
    <origin rpy="0 0 0" xyz="0 0 0"/>
  </joint>
  <link name="base_link">
    <inertial>
      <mass value="300.0"/>
      <origin rpy="0 0 0" xyz="0.0 0 0.20"/>
      <inertia ixx="10.659995736" ixy="0.0" ixz="0.0" iyy="22.499991" iyz="0.0" izz="28.659988536000004"/>
    </inertial>
    <visual>
      <origin rpy="1.5707963267948966 0 1.5707963267948966" xyz="0.0 0 0"/>
      <geometry>
        <mesh filename="package://mir_description/meshes/visual/mir_600_base.stl"/>
      </geometry>
      <material name="white">
        <color rgba="1 1 1 1"/>
      </material>
    </visual>
    <collision>
      <origin rpy="1.5707963267948966 0 1.5707963267948966" xyz="0.0 0 0"/>
      <geometry>
        <mesh filename="package://mir_description/meshes/collision/mir_600_base.stl"/>
      </geometry>
    </collision>
  </link>
  <!-- IMU -->
  <joint name="base_link_to_imu_joint" type="fixed">
    <parent link="base_link"/>
    <child link="imu_link"/>
    <origin rpy="0 0 0" xyz="0.0 0.0 0.25"/>
    <!-- same as real MiR -->
  </joint>
  <link name="imu_link"/>
  <!-- Create an alias for imu_link. This is necessary because the real MiR's
			TF has imu_link, but the imu_data topic is published in the imu_frame
			frame. -->
  <joint name="imu_link_to_imu_frame_joint" type="fixed">
    <parent link="imu_link"/>
    <child link="imu_frame"/>
    <origin rpy="0 0 0" xyz="0 0 0"/>
  </joint>
  <link name="imu_frame"/>
  <!-- Laser scanners -->
  <joint name="base_link_to_front_laser_joint" type="fixed">
    <parent link="base_link"/>
    <child link="front_laser_link"/>
    <origin rpy="0.0 0.0 0.7853981633974483" xyz="0.58985 0.370 0.1914"/>
    <!-- from visually matching up the meshes of the MiR and the laser scanner -->
  </joint>
  <link name="front_laser_link">
    <visual>
      <origin rpy="3.141592653589793 0 0" xyz="0.0 0.0 0.0"/>
      <geometry>
        <mesh filename="package://mir_description/meshes/visual/sick_lms-100.stl"/>
      </geometry>
      <!-- <xacro:insert_block name="material_yellow" /> -->
      <material name="black">
        <color rgba="0.1 0.1 0.1 1"/>
      </material>
    </visual>
    <collision>
      <origin rpy="3.141592653589793 0 0" xyz="0.0 0.0 0.0"/>
      <geometry>
        <mesh filename="package://mir_description/meshes/visual/sick_lms-100.stl"/>
      </geometry>
    </collision>
    <inertial>
      <mass value="2.0"/>
      <origin xyz="0 0 0"/>
      <inertia ixx="0.009708329449999999" ixy="0.0" ixz="0.0" iyy="0.0097601627626" iyz="0.0" izz="0.0080601634426"/>
    </inertial>
  </link>
  <joint name="base_link_to_back_laser_joint" type="fixed">
    <parent link="base_link"/>
    <child link="back_laser_link"/>
    <origin rpy="0.0 0.0 -2.356194490192345" xyz="-0.58985 -0.370 0.1914"/>
    <!-- from visually matching up the meshes of the MiR and the laser scanner -->
  </joint>
  <link name="back_laser_link">
    <visual>
      <origin rpy="3.141592653589793 0 0" xyz="0.0 0.0 0.0"/>
      <geometry>
        <mesh filename="package://mir_description/meshes/visual/sick_lms-100.stl"/>
      </geometry>
      <!-- <xacro:insert_block name="material_yellow" /> -->
      <material name="black">
        <color rgba="0.1 0.1 0.1 1"/>
      </material>
    </visual>
    <collision>
      <origin rpy="3.141592653589793 0 0" xyz="0.0 0.0 0.0"/>
      <geometry>
        <mesh filename="package://mir_description/meshes/visual/sick_lms-100.stl"/>
      </geometry>
    </collision>
    <inertial>
      <mass value="2.0"/>
      <origin xyz="0 0 0"/>
      <inertia ixx="0.009708329449999999" ixy="0.0" ixz="0.0" iyy="0.0097601627626" iyz="0.0" izz="0.0080601634426"/>
    </inertial>
  </link>
  <!-- Ultrasound sensors -->
  <joint name="us_1_joint" type="fixed">
    <!-- right ultrasound -->
    <parent link="base_link"/>
    <child link="us_1_frame"/>
    <origin rpy="0 0 0" xyz="0.45 -0.12 0.16 "/>
    <!-- from visually matching to the mesh of the MiR -->
  </joint>
  <link name="us_1_frame"/>
  <joint name="us_2_joint" type="fixed">
    <!-- left ultrasound -->
    <parent link="base_link"/>
    <child link="us_2_frame"/>
    <origin rpy="0 0 0" xyz="0.45 0.12 0.16 "/>
    <!-- from visually matching to the mesh of the MiR -->
  </joint>

  <link name="left_suspension_link">
  <inertial>
    <mass value="5.0"/> <!-- Adjust mass as needed -->
    <origin xyz="0 0 0" rpy="0 0 0"/>
    <inertia ixx="0.1" ixy="0" ixz="0" iyy="0.1" iyz="0" izz="0.1"/> <!-- Adjust inertia tensor -->
  </inertial>
  <visual>
    <origin xyz="0 0 0" rpy="0 0 0"/>
    <geometry>
      <cylinder length="0.2" radius="0.02"/> <!-- Example geometry for suspension -->
    </geometry>
    <material name="aluminum">
      <color rgba="0.5 0.5 0.5 1"/>
    </material>
  </visual>
</link>
<link name="right_suspension_link">
  <inertial>
    <mass value="5.0"/> <!-- Adjust mass as needed -->
    <origin xyz="0 0 0" rpy="0 0 0"/>
    <inertia ixx="0.1" ixy="0" ixz="0" iyy="0.1" iyz="0" izz="0.1"/> <!-- Adjust inertia tensor -->
  </inertial>
  <visual>
    <origin xyz="0 0 0" rpy="0 0 0"/>
    <geometry>
      <cylinder length="0.2" radius="0.02"/> <!-- Example geometry for suspension -->
    </geometry>
    <material name="aluminum">
      <color rgba="0.5 0.5 0.5 1"/>
    </material>
  </visual>
</link>
<joint name="left_suspension_joint" type="prismatic">
  <origin xyz="0.0 -0.33 -0.1" rpy="3.141592653589793 0 0"/> <!-- Position relative to base_link -->
  <parent link="base_link"/>
  <child link="left_suspension_link"/>
  <axis xyz="0 0 1"/> <!-- Allow movement along z-axis -->
  <limit lower="-0.2" upper="0.2" effort="1000.0" velocity="0.1"/> <!-- Adjust limits as needed -->
  <!-- Optional: Add Gazebo-specific suspension properties -->
  <gazebo>
    <spring>
      <stiffness>1000.0</stiffness> <!-- Spring stiffness -->
      <damping>50.0</damping>       <!-- Damping coefficient -->
      <reference_position>0.0</reference_position> <!-- Neutral position -->
    </spring>
  </gazebo>
</joint>
<joint name="right_suspension_joint" type="prismatic">
  <origin xyz="0.0 0.33 -0.1" rpy="3.141592653589793 0 0"/> <!-- Position relative to base_link -->
  <parent link="base_link"/>
  <child link="right_suspension_link"/>
  <axis xyz="0 0 1"/> <!-- Allow movement along z-axis -->
  <limit lower="-0.2" upper="0.2" effort="1000.0" velocity="0.1"/> <!-- Adjust limits as needed -->
  <!-- Optional: Add Gazebo-specific suspension properties -->
  <gazebo>
    <spring>
      <stiffness>1000.0</stiffness> <!-- Spring stiffness -->
      <damping>50.0</damping>       <!-- Damping coefficient -->
      <reference_position>0.0</reference_position> <!-- Neutral position -->
    </spring>
  </gazebo>
</joint>


  <link name="us_2_frame"/>
  <joint name="left_wheel_joint" type="continuous">
    <origin rpy="0 0 0" xyz="0.0 0.33 0.1"/>
    <parent link="left_suspension_link"/>
    <child link="left_wheel_link"/>
    <axis xyz="0 1 0"/>
    <limit effort="200" velocity="20.0"/>
  </joint>
  <link name="left_wheel_link">
    <inertial>
      <mass value="10.0"/>
      <origin rpy="1.5707963267948966 0 0" xyz="0 0 0"/>
      <inertia ixx="0.027083322500000007" ixy="0.0" ixz="0.0" iyy="0.027083322500000007" iyz="0.0" izz="0.05"/>
    </inertial>
    <visual>
      <origin rpy="1.5707963267948966 0 0.0" xyz="0 -0.025 0"/>
      <geometry>
        <mesh filename="package://mir_description/meshes/visual/mir_600_wheel.stl"/>
      </geometry>
      <material name="dark_grey">
        <color rgba="0.3 0.3 0.3 1"/>
      </material>
    </visual>
    <collision>
      <origin rpy="1.5707963267948966 0 -3.141592653589793" xyz="0 0 0"/>
      <geometry>
        <cylinder length="0.05" radius="0.1"/>
      </geometry>
    </collision>
  </link>
  <joint name="right_wheel_joint" type="continuous">
    <origin rpy="0 0 0" xyz="0.0 -0.33 0.1"/>
    <parent link="right_suspension_link"/>
    <child link="right_wheel_link"/>
    <axis xyz="0 1 0"/>
    <limit effort="200" velocity="20.0"/>
  </joint>
  <link name="right_wheel_link">
    <inertial>
      <mass value="10.0"/>
      <origin rpy="1.5707963267948966 0 0" xyz="0 0 0"/>
      <inertia ixx="0.027083322500000007" ixy="0.0" ixz="0.0" iyy="0.027083322500000007" iyz="0.0" izz="0.05"/>
    </inertial>
    <visual>
      <origin rpy="1.5707963267948966 0 3.141592653589793" xyz="0 0.025 0"/>
      <geometry>
        <mesh filename="package://mir_description/meshes/visual/mir_600_wheel.stl"/>
      </geometry>
      <material name="dark_grey">
        <color rgba="0.3 0.3 0.3 1"/>
      </material>
    </visual>
    <collision>
      <origin rpy="1.5707963267948966 0 -3.141592653589793" xyz="0 0 0"/>
      <geometry>
        <cylinder length="0.05" radius="0.1"/>
      </geometry>
    </collision>
  </link>
  <!-- Caster Suspensions -->
  <link name="fl_caster_suspension_link">
  <inertial>
    <mass value="5.0"/> <!-- Adjust mass as needed -->
    <origin xyz="0 0 0" rpy="0 0 0"/>
    <inertia ixx="0.1" ixy="0" ixz="0" iyy="0.1" iyz="0" izz="0.1"/> <!-- Adjust inertia tensor -->
  </inertial>
  <visual>
    <origin xyz="0 0 0" rpy="0 0 0"/>
    <geometry>
      <cylinder length="0.2" radius="0.02"/> <!-- Example geometry for suspension -->
    </geometry>
    <material name="aluminum">
      <color rgba="0.5 0.5 0.5 1"/>
    </material>
  </visual>
</link>
<link name="fr_caster_suspension_link">
  <inertial>
    <mass value="5.0"/> <!-- Adjust mass as needed -->
    <origin xyz="0 0 0" rpy="0 0 0"/>
    <inertia ixx="0.1" ixy="0" ixz="0" iyy="0.1" iyz="0" izz="0.1"/> <!-- Adjust inertia tensor -->
  </inertial>
  <visual>
    <origin xyz="0 0 0" rpy="0 0 0"/>
    <geometry>
      <cylinder length="0.2" radius="0.02"/> <!-- Example geometry for suspension -->
    </geometry>
    <material name="aluminum">
      <color rgba="0.5 0.5 0.5 1"/>
    </material>
  </visual>
</link>
<link name="bl_caster_suspension_link">
  <inertial>
    <mass value="5.0"/> <!-- Adjust mass as needed -->
    <origin xyz="0 0 0" rpy="0 0 0"/>
    <inertia ixx="0.1" ixy="0" ixz="0" iyy="0.1" iyz="0" izz="0.1"/> <!-- Adjust inertia tensor -->
  </inertial>
  <visual>
    <origin xyz="0 0 0" rpy="0 0 0"/>
    <geometry>
      <cylinder length="0.2" radius="0.02"/> <!-- Example geometry for suspension -->
    </geometry>
    <material name="aluminum">
      <color rgba="0.5 0.5 0.5 1"/>
    </material>
  </visual>
</link>
<link name="br_caster_suspension_link">
  <inertial>
    <mass value="5.0"/> <!-- Adjust mass as needed -->
    <origin xyz="0 0 0" rpy="0 0 0"/>
    <inertia ixx="0.1" ixy="0" ixz="0" iyy="0.1" iyz="0" izz="0.1"/> <!-- Adjust inertia tensor -->
  </inertial>
  <visual>
    <origin xyz="0 0 0" rpy="0 0 0"/>
    <geometry>
      <cylinder length="0.2" radius="0.02"/> <!-- Example geometry for suspension -->
    </geometry>
    <material name="aluminum">
      <color rgba="0.5 0.5 0.5 1"/>
    </material>
  </visual>
</link>
<!-- TODO: fixed linkt to pre_suspension from base, to suspension_link, to rotation_link -->
<joint name="fl_caster_suspension_joint" type="prismatic">
  <origin xyz="0.0 -0.0 -0.0" rpy="0 0 0"/> <!-- Position relative to base_link -->
  <parent link="fl_caster_rotation_link"/>
  <child link="fl_caster_suspension_link"/>
  <axis xyz="0 0 -1"/> <!-- Allow movement along z-axis -->
  <limit lower="-0.0" upper="0.2" effort="1000000.0" velocity="0.1"/> <!-- Adjust limits as needed -->
  <!-- Optional: Add Gazebo-specific suspension properties -->
  <gazebo>
    <spring>
      <stiffness>1000.0</stiffness> <!-- Spring stiffness -->
      <damping>50.0</damping>       <!-- Damping coefficient -->
      <reference_position>0.1</reference_position> <!-- Neutral position -->
    </spring>
  </gazebo>
</joint>
<joint name="fr_caster_suspension_joint" type="prismatic">
  <origin xyz="0.0 -0.0 -0.0" rpy="0 0 0"/> <!-- Position relative to base_link -->
  <parent link="fr_caster_rotation_link"/>
  <child link="fr_caster_suspension_link"/>
  <axis xyz="0 0 -1"/> <!-- Allow movement along z-axis -->
  <limit lower="-0.0" upper="0.2" effort="1000000.0" velocity="0.1"/> <!-- Adjust limits as needed -->
  <!-- Optional: Add Gazebo-specific suspension properties -->
  <gazebo>
    <spring>
      <stiffness>1000.0</stiffness> <!-- Spring stiffness -->
      <damping>50.0</damping>       <!-- Damping coefficient -->
      <reference_position>0.1</reference_position> <!-- Neutral position -->
    </spring>
    <!-- <physics>
      <ode>
        <implicitSpringDamper>true</implicitSpringDamper>
      </ode>
    </physics> -->
  </gazebo>
</joint>
<joint name="bl_caster_suspension_joint" type="prismatic">
  <origin xyz="0.0 -0.0 -0.0" rpy="0 0 0"/> <!-- Position relative to base_link -->
  <parent link="bl_caster_rotation_link"/>
  <child link="bl_caster_suspension_link"/>
  <axis xyz="0 0 -1"/> <!-- Allow movement along z-axis -->
  <limit lower="-0.0" upper="0.2" effort="1000000.0" velocity="0.1"/> <!-- Adjust limits as needed -->
  <!-- Optional: Add Gazebo-specific suspension properties -->
  <gazebo>
    <spring>
      <stiffness>1000.0</stiffness> <!-- Spring stiffness -->
      <damping>50.0</damping>       <!-- Damping coefficient -->
      <reference_position>0.1</reference_position> <!-- Neutral position -->
    </spring>
  </gazebo>
</joint>
<joint name="br_caster_suspension_joint" type="prismatic">
  <origin xyz="0.0 -0.0 -0.0" rpy="0 0 0"/> <!-- Position relative to base_link -->
  <parent link="br_caster_rotation_link"/>
  <child link="br_caster_suspension_link"/>
  <axis xyz="0 0 -1"/> <!-- Allow movement along z-axis -->
  <limit lower="-0.0" upper="0.2" effort="1000000.0" velocity="0.1"/> <!-- Adjust limits as needed -->
  <!-- Optional: Add Gazebo-specific suspension properties -->
  <gazebo>
    <spring>
      <stiffness>1000.0</stiffness> <!-- Spring stiffness -->
      <damping>50.0</damping>       <!-- Damping coefficient -->
      <reference_position>0.1</reference_position> <!-- Neutral position -->
    </spring>
  </gazebo>
</joint>

  <!-- caster hub -->
  <joint name="fl_caster_rotation_joint" type="continuous">
    <origin rpy="0 0 0" xyz="0.4915 0.3215 0.075"/>
    <parent link="base_link"/>
    <child link="fl_caster_rotation_link"/>
    <axis xyz="0 0 1"/>
    <dynamics damping="0.01" friction="0.0"/>
  </joint>
  <link name="fl_caster_rotation_link">
    <inertial>
      <!-- <origin xyz="0 0 -0.042500000044" rpy="${0.5 * pi} ${24 * deg_to_rad} ${1.5 * pi}" /> -->
      <origin rpy="0.4188790204786391 0 1.5707963267948966 " xyz="0 0 -0.042500000044"/>
      <mass value="0.3097539019"/>
      <inertia ixx="0.0005844517978" ixy="0" ixz="0" iyy="0.00052872551237" iyz="0" izz="0.00017923555074"/>
    </inertial>
    <visual>
      <origin rpy="0 0 0" xyz="0 0 0"/>
      <geometry>
        <mesh filename="package://mir_description/meshes/visual/caster_wheel_base.stl"/>
      </geometry>
      <material name="silver">
        <color rgba="0.79 0.82 0.93 1"/>
      </material>
    </visual>
    <collision>
      <origin rpy="0 0 0" xyz="0 0 0"/>
      <geometry>
        <mesh filename="package://mir_description/meshes/collision/caster_wheel_base.stl"/>
      </geometry>
    </collision>
  </link>
  <!-- caster wheel -->
  <joint name="fl_caster_wheel_joint" type="continuous">
    <origin rpy="0 0 0" xyz="-0.0382 0 -0.1"/>
    <parent link="fl_caster_suspension_link"/>
    <child link="fl_caster_wheel_link"/>
    <axis xyz="0 1 0"/>
  </joint>
  <link name="fl_caster_wheel_link">
    <inertial>
      <mass value="10.0"/>
      <origin rpy="1.5707963267948966 0 0" xyz="0 0 0"/>
      <inertia ixx="0.0075833303000000015" ixy="0.0" ixz="0.0" iyy="0.0075833303000000015" iyz="0.0" izz="0.0125"/>
    </inertial>
    <visual>
      <origin rpy="1.5707963267948966 0 0" xyz="0 0 0"/>
      <geometry>
        <mesh filename="package://mir_description/meshes/visual/mir_600_caster_wheel.stl"/>
      </geometry>
      <material name="dark_grey">
        <color rgba="0.3 0.3 0.3 1"/>
      </material>
    </visual>
    <collision>
      <origin rpy="1.5707963267948966 0 0" xyz="0 0 0"/>
      <geometry>
        <cylinder length="0.04" radius="0.05"/>
      </geometry>
    </collision>
  </link>
  <!-- caster hub -->
  <joint name="fr_caster_rotation_joint" type="continuous">
    <origin rpy="0 0 0" xyz="0.4915 -0.3215 0.075"/>
    <parent link="base_link"/>
    <child link="fr_caster_rotation_link"/>
    <axis xyz="0 0 1"/>
    <dynamics damping="0.01" friction="0.0"/>
  </joint>
  <link name="fr_caster_rotation_link">
    <inertial>
      <!-- <origin xyz="0 0 -0.042500000044" rpy="${0.5 * pi} ${24 * deg_to_rad} ${1.5 * pi}" /> -->
      <origin rpy="0.4188790204786391 0 1.5707963267948966 " xyz="0 0 -0.042500000044"/>
      <mass value="0.3097539019"/>
      <inertia ixx="0.0005844517978" ixy="0" ixz="0" iyy="0.00052872551237" iyz="0" izz="0.00017923555074"/>
    </inertial>
    <visual>
      <origin rpy="0 0 0" xyz="0 0 0"/>
      <geometry>
        <mesh filename="package://mir_description/meshes/visual/caster_wheel_base.stl"/>
      </geometry>
      <material name="silver">
        <color rgba="0.79 0.82 0.93 1"/>
      </material>
    </visual>
    <collision>
      <origin rpy="0 0 0" xyz="0 0 0"/>
      <geometry>
        <mesh filename="package://mir_description/meshes/collision/caster_wheel_base.stl"/>
      </geometry>
    </collision>
  </link>
  <!-- caster wheel -->
  <joint name="fr_caster_wheel_joint" type="continuous">
    <origin rpy="0 0 0" xyz="-0.0382 0 -0.1"/>
    <parent link="fr_caster_suspension_link"/>
    <child link="fr_caster_wheel_link"/>
    <axis xyz="0 1 0"/>
  </joint>
  <link name="fr_caster_wheel_link">
    <inertial>
      <mass value="10.0"/>
      <origin rpy="1.5707963267948966 0 0" xyz="0 0 0"/>
      <inertia ixx="0.0075833303000000015" ixy="0.0" ixz="0.0" iyy="0.0075833303000000015" iyz="0.0" izz="0.0125"/>
    </inertial>
    <visual>
      <origin rpy="1.5707963267948966 0 0" xyz="0 0 0"/>
      <geometry>
        <mesh filename="package://mir_description/meshes/visual/mir_600_caster_wheel.stl"/>
      </geometry>
      <material name="dark_grey">
        <color rgba="0.3 0.3 0.3 1"/>
      </material>
    </visual>
    <collision>
      <origin rpy="1.5707963267948966 0 0" xyz="0 0 0"/>
      <geometry>
        <cylinder length="0.04" radius="0.05"/>
      </geometry>
    </collision>
  </link>
  <!-- caster hub -->
  <joint name="bl_caster_rotation_joint" type="continuous">
    <origin rpy="0 0 0" xyz="-0.4885 0.3215 0.075"/>
    <parent link="base_link"/>
    <child link="bl_caster_rotation_link"/>
    <axis xyz="0 0 1"/>
    <dynamics damping="0.01" friction="0.0"/>
  </joint>
  <link name="bl_caster_rotation_link">
    <inertial>
      <!-- <origin xyz="0 0 -0.042500000044" rpy="${0.5 * pi} ${24 * deg_to_rad} ${1.5 * pi}" /> -->
      <origin rpy="0.4188790204786391 0 1.5707963267948966 " xyz="0 0 -0.042500000044"/>
      <mass value="0.3097539019"/>
      <inertia ixx="0.0005844517978" ixy="0" ixz="0" iyy="0.00052872551237" iyz="0" izz="0.00017923555074"/>
    </inertial>
    <visual>
      <origin rpy="0 0 0" xyz="0 0 0"/>
      <geometry>
        <mesh filename="package://mir_description/meshes/visual/caster_wheel_base.stl"/>
      </geometry>
      <material name="silver">
        <color rgba="0.79 0.82 0.93 1"/>
      </material>
    </visual>
    <collision>
      <origin rpy="0 0 0" xyz="0 0 0"/>
      <geometry>
        <mesh filename="package://mir_description/meshes/collision/caster_wheel_base.stl"/>
      </geometry>
    </collision>
  </link>
  <!-- caster wheel -->
  <joint name="bl_caster_wheel_joint" type="continuous">
    <origin rpy="0 0 0" xyz="-0.0382 0 -0.1"/>
    <parent link="bl_caster_suspension_link"/>
    <child link="bl_caster_wheel_link"/>
    <axis xyz="0 1 0"/>
  </joint>
  <link name="bl_caster_wheel_link">
    <inertial>
      <mass value="10.0"/>
      <origin rpy="1.5707963267948966 0 0" xyz="0 0 0"/>
      <inertia ixx="0.0075833303000000015" ixy="0.0" ixz="0.0" iyy="0.0075833303000000015" iyz="0.0" izz="0.0125"/>
    </inertial>
    <visual>
      <origin rpy="1.5707963267948966 0 0" xyz="0 0 0"/>
      <geometry>
        <mesh filename="package://mir_description/meshes/visual/mir_600_caster_wheel.stl"/>
      </geometry>
      <material name="dark_grey">
        <color rgba="0.3 0.3 0.3 1"/>
      </material>
    </visual>
    <collision>
      <origin rpy="1.5707963267948966 0 0" xyz="0 0 0"/>
      <geometry>
        <cylinder length="0.04" radius="0.05"/>
      </geometry>
    </collision>
  </link>
  <!-- caster hub -->
  <joint name="br_caster_rotation_joint" type="continuous">
    <origin rpy="0 0 0" xyz="-0.4885 -0.3215 0.075"/>
    <parent link="base_link"/>
    <child link="br_caster_rotation_link"/>
    <axis xyz="0 0 1"/>
    <dynamics damping="0.01" friction="0.0"/>
  </joint>
  <link name="br_caster_rotation_link">
    <inertial>
      <!-- <origin xyz="0 0 -0.042500000044" rpy="${0.5 * pi} ${24 * deg_to_rad} ${1.5 * pi}" /> -->
      <origin rpy="0.4188790204786391 0 1.5707963267948966 " xyz="0 0 -0.042500000044"/>
      <mass value="0.3097539019"/>
      <inertia ixx="0.0005844517978" ixy="0" ixz="0" iyy="0.00052872551237" iyz="0" izz="0.00017923555074"/>
    </inertial>
    <visual>
      <origin rpy="0 0 0" xyz="0 0 0"/>
      <geometry>
        <mesh filename="package://mir_description/meshes/visual/caster_wheel_base.stl"/>
      </geometry>
      <material name="silver">
        <color rgba="0.79 0.82 0.93 1"/>
      </material>
    </visual>
    <collision>
      <origin rpy="0 0 0" xyz="0 0 0"/>
      <geometry>
        <mesh filename="package://mir_description/meshes/collision/caster_wheel_base.stl"/>
      </geometry>
    </collision>
  </link>
  <!-- caster wheel -->
  <joint name="br_caster_wheel_joint" type="continuous">
    <origin rpy="0 0 0" xyz="-0.0382 0 -0.1"/>
    <parent link="br_caster_suspension_link"/>
    <child link="br_caster_wheel_link"/>
    <axis xyz="0 1 0"/>
  </joint>
  <link name="br_caster_wheel_link">
    <inertial>
      <mass value="10.0"/>
      <origin rpy="1.5707963267948966 0 0" xyz="0 0 0"/>
      <inertia ixx="0.0075833303000000015" ixy="0.0" ixz="0.0" iyy="0.0075833303000000015" iyz="0.0" izz="0.0125"/>
    </inertial>
    <visual>
      <origin rpy="1.5707963267948966 0 0" xyz="0 0 0"/>
      <geometry>
        <mesh filename="package://mir_description/meshes/visual/mir_600_caster_wheel.stl"/>
      </geometry>
      <material name="dark_grey">
        <color rgba="0.3 0.3 0.3 1"/>
      </material>
    </visual>
    <collision>
      <origin rpy="1.5707963267948966 0 0" xyz="0 0 0"/>
      <geometry>
        <cylinder length="0.04" radius="0.05"/>
      </geometry>
    </collision>
  </link>
  <joint name="base_link_surface_joint" type="fixed">
    <origin rpy="0 0 0" xyz="0.0 0 0.352"/>
    <parent link="base_link"/>
    <child link="surface"/>
    <axis xyz="0 0 1"/>
  </joint>
  <link name="surface"/>
  <!-- camera body, with origin at bottom screw mount -->
  <joint name="camera_joint" type="fixed">
    <origin rpy="0 0 0" xyz="0.62335 0 0.24"/>
    <parent link="base_link"/>
    <child link="camera_bottom_screw_frame"/>
  </joint>
  <link name="camera_bottom_screw_frame"/>
  <joint name="camera_link_joint" type="fixed">
    <origin rpy="0 0 0" xyz="0.010600000000000002 0.0175 0.0125"/>
    <parent link="camera_bottom_screw_frame"/>
    <child link="camera_link"/>
  </joint>
  <link name="camera_link">
    <visual>
      <!-- the mesh origin is at front plate in between the two infrared camera axes -->
      <origin rpy="1.5707963267948966 0 1.5707963267948966" xyz="0.0043 -0.0175 0"/>
      <geometry>
        <mesh filename="package://mir_description/meshes/visual/d435.dae"/>
      </geometry>
    </visual>
    <collision>
      <origin rpy="0 0 0" xyz="0 -0.0175 0"/>
      <geometry>
        <box size="0.02505 0.09 0.025"/>
      </geometry>
    </collision>
    <inertial>
      <!-- The following are not reliable values, and should not be used for modeling -->
      <mass value="0.072"/>
      <origin xyz="0 0 0"/>
      <inertia ixx="0.003881243" ixy="0.0" ixz="0.0" iyy="0.000498940" iyz="0.0" izz="0.003879257"/>
    </inertial>
  </link>
  <!-- camera depth joints and links -->
  <joint name="camera_depth_joint" type="fixed">
    <origin rpy="0 0 0" xyz="0 0 0"/>
    <parent link="camera_link"/>
    <child link="camera_depth_frame"/>
  </joint>
  <link name="camera_depth_frame"/>
  <joint name="camera_depth_optical_joint" type="fixed">
    <origin rpy="-1.5707963267948966 0 -1.5707963267948966" xyz="0 0 0"/>
    <parent link="camera_depth_frame"/>
    <child link="camera_depth_optical_frame"/>
  </joint>
  <link name="camera_depth_optical_frame"/>
  <!-- camera left IR joints and links -->
  <joint name="camera_infra1_joint" type="fixed">
    <origin rpy="0 0 0" xyz="0 0.0 0"/>
    <parent link="camera_link"/>
    <child link="camera_infra1_frame"/>
  </joint>
  <link name="camera_infra1_frame"/>
  <joint name="camera_infra1_optical_joint" type="fixed">
    <origin rpy="-1.5707963267948966 0 -1.5707963267948966" xyz="0 0 0"/>
    <parent link="camera_infra1_frame"/>
    <child link="camera_infra1_optical_frame"/>
  </joint>
  <link name="camera_infra1_optical_frame"/>
  <!-- camera right IR joints and links -->
  <joint name="camera_infra2_joint" type="fixed">
    <origin rpy="0 0 0" xyz="0 -0.05 0"/>
    <parent link="camera_link"/>
    <child link="camera_infra2_frame"/>
  </joint>
  <link name="camera_infra2_frame"/>
  <joint name="camera_infra2_optical_joint" type="fixed">
    <origin rpy="-1.5707963267948966 0 -1.5707963267948966" xyz="0 0 0"/>
    <parent link="camera_infra2_frame"/>
    <child link="camera_infra2_optical_frame"/>
  </joint>
  <link name="camera_infra2_optical_frame"/>
  <!-- camera color joints and links -->
  <joint name="camera_color_joint" type="fixed">
    <origin rpy="0 0 0" xyz="0 0.015 0"/>
    <parent link="camera_link"/>
    <child link="camera_color_frame"/>
  </joint>
  <link name="camera_color_frame"/>
  <joint name="camera_color_optical_joint" type="fixed">
    <origin rpy="-1.5707963267948966 0 -1.5707963267948966" xyz="0 0 0"/>
    <parent link="camera_color_frame"/>
    <child link="camera_color_optical_frame"/>
  </joint>
  <link name="camera_color_optical_frame"/>
  <!-- <xacro:if value="${add_plug}">
      <xacro:usb_plug parent="${name}_link" name="${name}_usb_plug">
        <origin xyz="${d435_cam_mount_from_center_offset - 0.02095} ${-d435_cam_depth_py - 0.0353} 0" rpy="0 0 0"/>
      </xacro:usb_plug>
    </xacro:if> -->
  <!-- Insert a match logo on both sides of the mobile robot -->
  <!-- <xacro:match_logo parent="base_link" locationprefix="left" location_dx="${mir_600_match_logo_dx}" location_dy="${mir_600_match_logo_dy}" location_dz="${mir_600_match_logo_dz}"/>
		<xacro:match_logo parent="base_link" locationprefix="right" location_dx="${mir_600_match_logo_dx}" location_dy="${-1 * mir_600_match_logo_dy}" location_dz="${mir_600_match_logo_dz}" orientation="${pi}"/> -->
  <!-- top module -->
  <link name="top_module">
    <inertial>
      <mass value="100.0"/>
      <origin rpy="0 0 0" xyz="0.0 0 0.25"/>
      <inertia ixx="8.984163073000001" ixy="0.0" ixz="0.0" iyy="17.270826425000003" iyz="0.0" izz="22.088324498000002"/>
    </inertial>
    <visual>
      <origin rpy="0 0 -1.5707963267948966" xyz="0.0 0 0"/>
      <geometry>
        <mesh filename="package://mir_description/meshes/visual/mir_600_top_module.stl" scale="0.001 0.001 0.001"/>
      </geometry>
      <material name="white">
        <color rgba="1 1 1 1"/>
      </material>
    </visual>
    <collision>
      <origin rpy="0 0 -1.5707963267948966" xyz="0.0 0 0"/>
      <geometry>
        <mesh filename="package://mir_description/meshes/collision/mir_600_top_module.stl" scale="0.001 0.001 0.001"/>
      </geometry>
    </collision>
  </link>
  <gazebo reference="top_module">
    <material>Gazebo/Grey</material>
  </gazebo>
  <joint name="top_module_joint" type="fixed">
    <origin rpy="0 0 0" xyz="0 0 0.832"/>
    <parent link="base_link"/>
    <child link="top_module"/>
    <axis xyz="0 0 1"/>
  </joint>
  <link name="left_lift_bottom">
    <inertial>
      <mass value="30.0"/>
      <origin rpy="0 0 0" xyz="0 0 0.15"/>
      <inertia ixx="0.32499986999999997" ixy="0.0" ixz="0.0" iyy="0.32499986999999997" iyz="0.0" izz="0.19999992000000003"/>
    </inertial>
    <visual>
      <origin rpy="1.5707963267948966 0 0.0" xyz="0 0 0"/>
      <geometry>
        <mesh filename="package://mir_description/meshes/visual/mir_600_lift_bot.stl"/>
      </geometry>
      <material name="white">
        <color rgba="1 1 1 1"/>
      </material>
    </visual>
    <collision>
      <origin rpy="1.5707963267948966 0 0.0" xyz="0 0 0"/>
      <geometry>
        <mesh filename="package://mir_description/meshes/collision/mir_600_lift_bot.stl"/>
      </geometry>
    </collision>
  </link>
  <gazebo reference="left_lift_bottom">
    <material>Gazebo/DarkGrey</material>
  </gazebo>
  <joint name="left_lift_bottom_joint" type="fixed">
    <origin rpy="0 0 0" xyz="0.549 0.318 -0.49"/>
    <parent link="top_module"/>
    <child link="left_lift_bottom"/>
    <axis xyz="0 0 1"/>
  </joint>
  <link name="right_lift_bottom">
    <inertial>
      <mass value="30.0"/>
      <origin rpy="0 0 0" xyz="0 0 0.15"/>
      <inertia ixx="0.32499986999999997" ixy="0.0" ixz="0.0" iyy="0.32499986999999997" iyz="0.0" izz="0.19999992000000003"/>
    </inertial>
    <visual>
      <origin rpy="1.5707963267948966 0 0.0" xyz="0 0 0"/>
      <geometry>
        <mesh filename="package://mir_description/meshes/visual/mir_600_lift_bot.stl"/>
      </geometry>
      <material name="white">
        <color rgba="1 1 1 1"/>
      </material>
    </visual>
    <collision>
      <origin rpy="1.5707963267948966 0 0.0" xyz="0 0 0"/>
      <geometry>
        <mesh filename="package://mir_description/meshes/collision/mir_600_lift_bot.stl"/>
      </geometry>
    </collision>
  </link>
  <gazebo reference="right_lift_bottom">
    <material>Gazebo/DarkGrey</material>
  </gazebo>
  <joint name="right_lift_bottom_joint" type="fixed">
    <origin rpy="0 0 0" xyz="0.549 -0.318 -0.49"/>
    <parent link="top_module"/>
    <child link="right_lift_bottom"/>
    <axis xyz="0 0 1"/>
  </joint>
  <!-- Camera -->
  <!--link name="camera_link">
		<collision>
			<origin xyz="0 0 0" rpy="0 0 0"/>
			<geometry>
				<box size="0.1 0.1 0.1"/>
			</geometry>
		</collision>
		<visual>
			<origin xyz="0 0 0" rpy="0 0 0"/>
			<geometry>
				<mesh filename="package://mir_description/meshes/visual/realsense.dae" />
			</geometry>
		</visual>
		<inertial>
			<mass value="1e-5" />
			<origin xyz="0 0 0" rpy="0 0 0"/>
			<inertia ixx="1e-6" ixy="0" ixz="0" iyy="1e-6" iyz="0" izz="1e-6" />
		</inertial>
		</link>

		<joint name="camera_joint" type="fixed">
			<axis xyz="0 1 0" />
			<origin xyz="0.42 0 0.27" rpy="0 0.2 0"/-->
  <!--set the position of the realsense-->
  <!--parent link="${tf_prefix}base_link"/>
			<child link="camera_link"/>
		</joint-->
  <!-- generate an optical frame http://www.ros.org/reps/rep-0103.html#suffix-frames
			so that ros and opencv can operate on the camera frame correctly -->
  <!--joint name="camera_optical_joint" type="fixed"-->
  <!-- these values have to be these values otherwise the gazebo camera image
				won't be aligned properly with the frame it is supposedly originating from -->
  <!--origin xyz="0 0 0" rpy="-1.5708 0 -1.5708"/>
			<parent link="camera_link"/>
			<child link="camera_link_optical"/>
		</joint>

		<link name="camera_link_optical"-->
  <!--/link-->
  <!-- Set Gazebo material for the base -->
  <gazebo reference="base_link">
    <material>Gazebo/Grey</material>
  </gazebo>
  <gazebo reference="left_wheel_link">
    <material>Gazebo/DarkGrey</material>
  </gazebo>
  <gazebo reference="right_wheel_link">
    <material>Gazebo/DarkGrey</material>
  </gazebo>
  <gazebo reference="fl_caster_rotation_link">
    <material>Gazebo/Grey</material>
  </gazebo>
  <gazebo reference="fl_caster_wheel_link">
    <material>Gazebo/DarkGrey</material>
  </gazebo>
  <gazebo reference="fr_caster_rotation_link">
    <material>Gazebo/Grey</material>
  </gazebo>
  <gazebo reference="fr_caster_wheel_link">
    <material>Gazebo/DarkGrey</material>
  </gazebo>
  <gazebo reference="bl_caster_rotation_link">
    <material>Gazebo/Grey</material>
  </gazebo>
  <gazebo reference="bl_caster_wheel_link">
    <material>Gazebo/DarkGrey</material>
  </gazebo>
  <gazebo reference="br_caster_rotation_link">
    <material>Gazebo/Grey</material>
  </gazebo>
  <gazebo reference="br_caster_wheel_link">
    <material>Gazebo/DarkGrey</material>
  </gazebo>
  <transmission name="left_wheel_trans">
    <type>transmission_interface/SimpleTransmission</type>
    <joint name="left_wheel_joint">
      <hardwareInterface>hardware_interface/VelocityJointInterface</hardwareInterface>
    </joint>
    <actuator name="left_wheel_motor">
      <hardwareInterface>hardware_interface/VelocityJointInterface</hardwareInterface>
      <mechanicalReduction>1</mechanicalReduction>
    </actuator>
  </transmission>
  <transmission name="right_wheel_trans">
    <type>transmission_interface/SimpleTransmission</type>
    <joint name="right_wheel_joint">
      <hardwareInterface>hardware_interface/VelocityJointInterface</hardwareInterface>
    </joint>
    <actuator name="right_wheel_motor">
      <hardwareInterface>hardware_interface/VelocityJointInterface</hardwareInterface>
      <mechanicalReduction>1</mechanicalReduction>
    </actuator>
  </transmission>
  <gazebo reference="imu_link">
    <gravity>true</gravity>
    <sensor name="imu_sensor" type="imu">
      <always_on>true</always_on>
      <update_rate>100</update_rate>
      <!-- this is not the publish rate -->
      <visualize>true</visualize>
      <topic>__default_topic__</topic>
      <plugin filename="libgazebo_ros_imu_sensor.so" name="imu_plugin">
        <robotNamespace>/</robotNamespace>
        <topicName>imu_data</topicName>
        <bodyName>imu_link</bodyName>
        <updateRateHZ>50.0</updateRateHZ>
        <!-- this is the publish rate -->
        <gaussianNoise>2.8900000000000004e-08</gaussianNoise>
        <xyzOffset>0 0 0</xyzOffset>
        <rpyOffset>0 0 0</rpyOffset>
        <frameName>imu_frame</frameName>
        <!-- from real MiR -->
      </plugin>
      <pose>0 0 0 0 0 0</pose>
    </sensor>
  </gazebo>
  <gazebo reference="front_laser_link">
    <material name="black">
      <color rgba="0.1 0.1 0.1 1"/>
    </material>
    <sensor name="front_laser_link" type="ray">
      <pose>0 0 0 0 0 0</pose>
      <visualize>false</visualize>
      <update_rate>12.5</update_rate>
      <ray>
        <scan>
          <horizontal>
            <samples>541</samples>
            <resolution>1</resolution>
            <!-- has to be 1; actual resolution will be computed from number of samples + min_angle/max_angle -->
            <min_angle>-2.35619449615</min_angle>
            <max_angle>2.35619449615</max_angle>
          </horizontal>
        </scan>
        <range>
          <min>0.05</min>
          <max>29.0</max>
          <resolution>0.01</resolution>
        </range>
        <noise>
          <type>gaussian</type>
          <!-- Noise parameters based on published spec for S300 achieving
									"+-29mm" accuracy at range < 3m (~0.01 of the range) at
									1 sigma. -->
          <mean>0.0</mean>
          <stddev>0.01</stddev>
        </noise>
      </ray>
      <plugin filename="libgazebo_ros_laser.so" name="gazebo_ros_front_laser_link_controller">
        <!-- no tf_prefix, plugin always uses a tf_prefix (if none is set it uses robotNamespace) -->
        <robotNamespace>/</robotNamespace>
        <frameName>front_laser_link</frameName>
        <topicName>f_scan</topicName>
      </plugin>
    </sensor>
  </gazebo>
  <gazebo reference="back_laser_link">
    <material name="black">
      <color rgba="0.1 0.1 0.1 1"/>
    </material>
    <sensor name="back_laser_link" type="ray">
      <pose>0 0 0 0 0 0</pose>
      <visualize>false</visualize>
      <update_rate>12.5</update_rate>
      <ray>
        <scan>
          <horizontal>
            <samples>541</samples>
            <resolution>1</resolution>
            <!-- has to be 1; actual resolution will be computed from number of samples + min_angle/max_angle -->
            <min_angle>-2.35619449615</min_angle>
            <max_angle>2.35619449615</max_angle>
          </horizontal>
        </scan>
        <range>
          <min>0.05</min>
          <max>29.0</max>
          <resolution>0.01</resolution>
        </range>
        <noise>
          <type>gaussian</type>
          <!-- Noise parameters based on published spec for S300 achieving
									"+-29mm" accuracy at range < 3m (~0.01 of the range) at
									1 sigma. -->
          <mean>0.0</mean>
          <stddev>0.01</stddev>
        </noise>
      </ray>
      <plugin filename="libgazebo_ros_laser.so" name="gazebo_ros_back_laser_link_controller">
        <!-- no tf_prefix, plugin always uses a tf_prefix (if none is set it uses robotNamespace) -->
        <robotNamespace>/</robotNamespace>
        <frameName>back_laser_link</frameName>
        <topicName>b_scan</topicName>
      </plugin>
    </sensor>
  </gazebo>
  <!-- disabled, because it doesn't make a difference in Gazebo: -->
  <!-- <xacro:set_all_wheel_frictions tf_prefix="${tf_prefix}"/> -->
  <!-- This part of the file looks like it is not necessary for the correct function of the urdf files.-->
  <!-- Remove this part in a second iteration when all functions are working like they are supposed to be-->
  <!-- <xacro:macro name="diff_controller_plugin_gazebo" params="prefix left_wheel_joint right_wheel_joint wheel_separation wheel_radius">
			<gazebo>
			<plugin name="diff_drive_controller" filename="libgazebo_ros_diff_drive.so">
				<legacyMode>false</legacyMode>
				<alwaysOn>true</alwaysOn>
				<updateRate>1000.0</updateRate>
				<leftJoint>${left_wheel_joint}</leftJoint>
				<rightJoint>${right_wheel_joint}</rightJoint>
				<wheelSeparation>${wheel_separation}</wheelSeparation>
				<wheelDiameter>${2*wheel_radius}</wheelDiameter>
				<wheelTorque>10</wheelTorque>
				<publishTf>1</publishTf>
				<odometryFrame>map</odometryFrame>
				<commandTopic>mobile_base_controller/cmd_vel</commandTopic>
				<odometryTopic>mobile_base_controller/odom</odometryTopic>
				<robotBaseFrame>base_footprint</robotBaseFrame>
				<wheelAcceleration>2.8</wheelAcceleration>
				<publishWheelJointState>true</publishWheelJointState>
				<publishWheelTF>false</publishWheelTF>
				<odometrySource>world</odometrySource>
				<rosDebugLevel>Debug</rosDebugLevel>
			</plugin>
			</gazebo>
		</xacro:macro> -->
  <!-- <xacro:macro name="set_wheel_friction" params="link friction">
			<gazebo reference="${link}">
			<mu1 value="${friction}"/>
			<mu2 value="${friction}"/>
			<kp value="10000000.0"/>
			<kd value="1.0"/>
			</gazebo>
		</xacro:macro>

		<xacro:macro name="set_all_wheel_frictions" params="prefix">
			<xacro:set_wheel_friction link="${prefix}left_wheel_link" friction="200"/>
			<xacro:set_wheel_friction link="${prefix}right_wheel_link" friction="200"/>
			<xacro:set_wheel_friction link="${prefix}fl_caster_wheel_link" friction="1"/>
			<xacro:set_wheel_friction link="${prefix}fr_caster_wheel_link" friction="1"/>
			<xacro:set_wheel_friction link="${prefix}bl_caster_wheel_link" friction="1"/>
			<xacro:set_wheel_friction link="${prefix}br_caster_wheel_link" friction="1"/>
		</xacro:macro> -->
  <!-- <p3d_base_controller tf_prefix="${tf_prefix}" /> -->
  <!-- Settings for the camera of the robot to work in the simulation environment-->
  <!--gazebo reference="camera_link">  
			<sensor type="depth" name="camera">
			<plugin name="kinect_camera_controller" filename="libgazebo_ros_openni_kinect.so">
				<cameraName>camera</cameraName>
				<alwaysOn>true</alwaysOn>
				<updateRate>10</updateRate>
				<imageTopicName>rgb/image_raw</imageTopicName>
				<depthImageTopicName>depth/image_raw</depthImageTopicName>
				<pointCloudTopicName>depth/points</pointCloudTopicName>
				<cameraInfoTopicName>rgb/camera_info</cameraInfoTopicName>
				<depthImageCameraInfoTopicName>depth/camera_info</depthImageCameraInfoTopicName>
				<frameName>camera_link_optical</frameName>
				<baseline>0.1</baseline>
				<distortion_k1>0.0</distortion_k1>
				<distortion_k2>0.0</distortion_k2>
				<distortion_k3>0.0</distortion_k3>
				<distortion_t1>0.0</distortion_t1>
				<distortion_t2>0.0</distortion_t2>
				<pointCloudCutoff>0.4</pointCloudCutoff>
			</plugin>
			</sensor>
		</gazebo-->
  <gazebo>
    <plugin filename="libgazebo_ros_control.so" name="gazebo_ros_control">
      <controlPeriod>0.001</controlPeriod>
      <legacyModeNS>true</legacyModeNS>
    </plugin>
  </gazebo>
  <gazebo>
    <plugin filename="libgazebo_ros_p3d.so" name="p3d_base_controller">
      <robotNamespace></robotNamespace>
      <alwaysOn>true</alwaysOn>
      <updateRate>50.0</updateRate>
      <bodyName>base_footprint</bodyName>
      <topicName>ground_truth</topicName>
      <gaussianNoise>0.01</gaussianNoise>
      <frameName>map</frameName>
      <xyzOffsets>0 0 0</xyzOffsets>
      <rpyOffsets>0 0 0</rpyOffsets>
    </plugin>
  </gazebo>
</robot>

